[2022-12-12 01:18:02][WARNING][log.py:241:log_response]：Not Found: /
[2022-12-12 01:18:04][WARNING][log.py:241:log_response]：Not Found: /
[2022-12-12 01:18:09][WARNING][log.py:241:log_response]：Not Found: /
[2022-12-12 01:18:39][WARNING][log.py:241:log_response]：Not Found: /
[2022-12-12 01:32:01][WARNING][log.py:241:log_response]：Not Found: /
[2022-12-12 01:33:01][WARNING][log.py:241:log_response]：Not Found: /
[2022-12-12 01:38:02][WARNING][log.py:241:log_response]：Not Found: /
[2022-12-12 01:40:04][WARNING][log.py:241:log_response]：Not Found: /
[2022-12-12 01:40:05][WARNING][log.py:241:log_response]：Not Found: /
[2022-12-12 01:40:09][WARNING][log.py:241:log_response]：Not Found: /
[2022-12-12 01:40:14][WARNING][log.py:241:log_response]：Not Found: /
[2022-12-12 01:40:22][WARNING][log.py:241:log_response]：Not Found: /
[2022-12-12 01:40:22][WARNING][log.py:241:log_response]：Not Found: /
[2022-12-12 01:40:24][WARNING][log.py:241:log_response]：Not Found: /
[2022-12-12 01:40:54][WARNING][log.py:241:log_response]：Not Found: /
[2022-12-12 01:49:34][WARNING][log.py:241:log_response]：Not Found: /
[2022-12-12 01:49:35][WARNING][log.py:241:log_response]：Not Found: /
[2022-12-12 01:49:41][WARNING][log.py:241:log_response]：Not Found: /
[2022-12-12 01:50:18][WARNING][log.py:241:log_response]：Not Found: /
[2022-12-12 01:50:19][WARNING][log.py:241:log_response]：Not Found: /
[2022-12-12 01:50:24][WARNING][log.py:241:log_response]：Not Found: /
[2022-12-12 01:51:09][WARNING][log.py:241:log_response]：Not Found: /
[2022-12-12 01:51:10][WARNING][log.py:241:log_response]：Not Found: /
[2022-12-12 01:51:15][WARNING][log.py:241:log_response]：Not Found: /
[2022-12-12 01:51:30][WARNING][log.py:241:log_response]：Not Found: /
[2022-12-12 01:51:31][WARNING][log.py:241:log_response]：Not Found: /
[2022-12-12 01:51:36][WARNING][log.py:241:log_response]：Not Found: /
[2022-12-12 01:52:07][WARNING][log.py:241:log_response]：Not Found: /
[2022-12-12 01:52:08][WARNING][log.py:241:log_response]：Not Found: /
[2022-12-12 01:52:09][WARNING][log.py:241:log_response]：Not Found: /
[2022-12-12 01:52:10][WARNING][log.py:241:log_response]：Not Found: /
[2022-12-12 01:52:15][WARNING][log.py:241:log_response]：Not Found: /
[2022-12-12 01:52:25][WARNING][log.py:241:log_response]：Not Found: /
[2022-12-12 01:52:26][WARNING][log.py:241:log_response]：Not Found: /
[2022-12-12 01:52:31][WARNING][log.py:241:log_response]：Not Found: /
[2022-12-12 01:54:52][WARNING][log.py:241:log_response]：Not Found: /
[2022-12-12 01:54:57][WARNING][log.py:241:log_response]：Not Found: /
[2022-12-12 01:55:09][WARNING][log.py:241:log_response]：Not Found: /
[2022-12-12 01:55:22][WARNING][log.py:241:log_response]：Not Found: /
[2022-12-12 01:55:23][WARNING][log.py:241:log_response]：Not Found: /
[2022-12-12 01:55:28][WARNING][log.py:241:log_response]：Not Found: /
[2022-12-12 01:55:28][WARNING][log.py:241:log_response]：Not Found: /
[2022-12-12 01:56:00][WARNING][log.py:241:log_response]：Not Found: /
[2022-12-12 01:56:00][WARNING][log.py:241:log_response]：Not Found: /
[2022-12-12 01:56:32][WARNING][log.py:241:log_response]：Not Found: /
[2022-12-12 01:56:32][WARNING][log.py:241:log_response]：Not Found: /
[2022-12-12 01:56:33][WARNING][log.py:241:log_response]：Not Found: /
[2022-12-12 01:56:34][WARNING][log.py:241:log_response]：Not Found: /
[2022-12-12 01:56:35][WARNING][log.py:241:log_response]：Not Found: /
[2022-12-12 01:56:38][WARNING][log.py:241:log_response]：Not Found: /
[2022-12-12 01:56:43][WARNING][log.py:241:log_response]：Not Found: /
[2022-12-12 01:57:13][WARNING][log.py:241:log_response]：Not Found: /
[2022-12-12 01:57:24][WARNING][log.py:241:log_response]：Not Found: /
[2022-12-12 01:57:25][WARNING][log.py:241:log_response]：Not Found: /
[2022-12-12 01:57:30][WARNING][log.py:241:log_response]：Not Found: /
[2022-12-12 01:57:50][WARNING][log.py:241:log_response]：Not Found: /
[2022-12-12 01:58:00][WARNING][log.py:241:log_response]：Not Found: /
[2022-12-12 01:58:04][WARNING][log.py:241:log_response]：Not Found: /
[2022-12-12 01:58:22][WARNING][log.py:241:log_response]：Not Found: /
[2022-12-12 01:59:00][WARNING][log.py:241:log_response]：Not Found: /
[2022-12-12 01:59:30][WARNING][log.py:241:log_response]：Not Found: /
[2022-12-12 01:59:40][WARNING][log.py:241:log_response]：Not Found: /
[2022-12-12 01:59:57][WARNING][log.py:241:log_response]：Not Found: /
[2022-12-12 01:59:57][WARNING][log.py:241:log_response]：Not Found: /
[2022-12-12 02:00:27][WARNING][log.py:241:log_response]：Not Found: /
[2022-12-12 02:00:59][WARNING][log.py:241:log_response]：Not Found: /
[2022-12-12 02:01:27][WARNING][log.py:241:log_response]：Not Found: /
[2022-12-12 02:04:01][WARNING][log.py:241:log_response]：Not Found: /
[2022-12-12 02:06:27][WARNING][log.py:241:log_response]：Not Found: /
[2022-12-12 02:12:24][WARNING][log.py:241:log_response]：Not Found: /
[2022-12-12 02:12:33][WARNING][log.py:241:log_response]：Not Found: /
[2022-12-12 02:12:34][WARNING][log.py:241:log_response]：Not Found: /
[2022-12-12 02:12:39][WARNING][log.py:241:log_response]：Not Found: /
[2022-12-12 02:14:01][WARNING][log.py:241:log_response]：Not Found: /
[2022-12-12 02:17:36][WARNING][log.py:241:log_response]：Not Found: /
[2022-12-12 02:18:08][WARNING][log.py:241:log_response]：Not Found: /
[2022-12-12 02:18:10][WARNING][log.py:241:log_response]：Not Found: /
[2022-12-12 02:18:15][WARNING][log.py:241:log_response]：Not Found: /
[2022-12-12 02:18:45][WARNING][log.py:241:log_response]：Not Found: /
[2022-12-12 02:19:42][WARNING][log.py:241:log_response]：Not Found: /
[2022-12-12 02:19:45][WARNING][log.py:241:log_response]：Not Found: /
[2022-12-12 02:21:57][WARNING][log.py:241:log_response]：Not Found: /
[2022-12-12 02:22:08][ERROR][views.py:59:process_image]：Expecting value: line 1 column 1 (char 0)
[2022-12-12 02:22:08][ERROR][log.py:241:log_response]：Internal Server Error: /process/process_image
Traceback (most recent call last):
  File "/Users/monstar/Desktop/yang/python/real-image/code/django/real_image/process/views.py", line 20, in process_image
    requestBody = json.loads(request.body)
  File "/usr/local/Cellar/python@3.9/3.9.12/Frameworks/Python.framework/Versions/3.9/lib/python3.9/json/__init__.py", line 346, in loads
    return _default_decoder.decode(s)
  File "/usr/local/Cellar/python@3.9/3.9.12/Frameworks/Python.framework/Versions/3.9/lib/python3.9/json/decoder.py", line 337, in decode
    obj, end = self.raw_decode(s, idx=_w(s, 0).end())
  File "/usr/local/Cellar/python@3.9/3.9.12/Frameworks/Python.framework/Versions/3.9/lib/python3.9/json/decoder.py", line 355, in raw_decode
    raise JSONDecodeError("Expecting value", s, err.value) from None
json.decoder.JSONDecodeError: Expecting value: line 1 column 1 (char 0)

During handling of the above exception, another exception occurred:

Traceback (most recent call last):
  File "/usr/local/lib/python3.9/site-packages/django/core/handlers/exception.py", line 55, in inner
    response = get_response(request)
  File "/usr/local/lib/python3.9/site-packages/django/core/handlers/base.py", line 197, in _get_response
    response = wrapped_callback(request, *callback_args, **callback_kwargs)
  File "/usr/local/lib/python3.9/site-packages/django/views/decorators/csrf.py", line 54, in wrapped_view
    return view_func(*args, **kwargs)
  File "/Users/monstar/Desktop/yang/python/real-image/code/django/real_image/process/views.py", line 60, in process_image
    return errResponse(e)
  File "/Users/monstar/Desktop/yang/python/real-image/code/django/real_image/process/views.py", line 69, in errResponse
    return HttpResponse(json.dumps(res, ensure_ascii=False),
  File "/usr/local/Cellar/python@3.9/3.9.12/Frameworks/Python.framework/Versions/3.9/lib/python3.9/json/__init__.py", line 234, in dumps
    return cls(
  File "/usr/local/Cellar/python@3.9/3.9.12/Frameworks/Python.framework/Versions/3.9/lib/python3.9/json/encoder.py", line 199, in encode
    chunks = self.iterencode(o, _one_shot=True)
  File "/usr/local/Cellar/python@3.9/3.9.12/Frameworks/Python.framework/Versions/3.9/lib/python3.9/json/encoder.py", line 257, in iterencode
    return _iterencode(o, 0)
  File "/usr/local/Cellar/python@3.9/3.9.12/Frameworks/Python.framework/Versions/3.9/lib/python3.9/json/encoder.py", line 179, in default
    raise TypeError(f'Object of type {o.__class__.__name__} '
TypeError: Object of type JSONDecodeError is not JSON serializable
[2022-12-12 02:22:10][ERROR][views.py:59:process_image]：Expecting value: line 1 column 1 (char 0)
[2022-12-12 02:22:10][ERROR][log.py:241:log_response]：Internal Server Error: /process/process_image
Traceback (most recent call last):
  File "/Users/monstar/Desktop/yang/python/real-image/code/django/real_image/process/views.py", line 20, in process_image
    requestBody = json.loads(request.body)
  File "/usr/local/Cellar/python@3.9/3.9.12/Frameworks/Python.framework/Versions/3.9/lib/python3.9/json/__init__.py", line 346, in loads
    return _default_decoder.decode(s)
  File "/usr/local/Cellar/python@3.9/3.9.12/Frameworks/Python.framework/Versions/3.9/lib/python3.9/json/decoder.py", line 337, in decode
    obj, end = self.raw_decode(s, idx=_w(s, 0).end())
  File "/usr/local/Cellar/python@3.9/3.9.12/Frameworks/Python.framework/Versions/3.9/lib/python3.9/json/decoder.py", line 355, in raw_decode
    raise JSONDecodeError("Expecting value", s, err.value) from None
json.decoder.JSONDecodeError: Expecting value: line 1 column 1 (char 0)

During handling of the above exception, another exception occurred:

Traceback (most recent call last):
  File "/usr/local/lib/python3.9/site-packages/django/core/handlers/exception.py", line 55, in inner
    response = get_response(request)
  File "/usr/local/lib/python3.9/site-packages/django/core/handlers/base.py", line 197, in _get_response
    response = wrapped_callback(request, *callback_args, **callback_kwargs)
  File "/usr/local/lib/python3.9/site-packages/django/views/decorators/csrf.py", line 54, in wrapped_view
    return view_func(*args, **kwargs)
  File "/Users/monstar/Desktop/yang/python/real-image/code/django/real_image/process/views.py", line 60, in process_image
    return errResponse(e)
  File "/Users/monstar/Desktop/yang/python/real-image/code/django/real_image/process/views.py", line 69, in errResponse
    return HttpResponse(json.dumps(res, ensure_ascii=False),
  File "/usr/local/Cellar/python@3.9/3.9.12/Frameworks/Python.framework/Versions/3.9/lib/python3.9/json/__init__.py", line 234, in dumps
    return cls(
  File "/usr/local/Cellar/python@3.9/3.9.12/Frameworks/Python.framework/Versions/3.9/lib/python3.9/json/encoder.py", line 199, in encode
    chunks = self.iterencode(o, _one_shot=True)
  File "/usr/local/Cellar/python@3.9/3.9.12/Frameworks/Python.framework/Versions/3.9/lib/python3.9/json/encoder.py", line 257, in iterencode
    return _iterencode(o, 0)
  File "/usr/local/Cellar/python@3.9/3.9.12/Frameworks/Python.framework/Versions/3.9/lib/python3.9/json/encoder.py", line 179, in default
    raise TypeError(f'Object of type {o.__class__.__name__} '
TypeError: Object of type JSONDecodeError is not JSON serializable
[2022-12-12 02:22:17][ERROR][views.py:59:process_image]：Expecting value: line 1 column 1 (char 0)
[2022-12-12 02:22:17][ERROR][log.py:241:log_response]：Internal Server Error: /process/process_image
Traceback (most recent call last):
  File "/Users/monstar/Desktop/yang/python/real-image/code/django/real_image/process/views.py", line 20, in process_image
    requestBody = json.loads(request.body)
  File "/usr/local/Cellar/python@3.9/3.9.12/Frameworks/Python.framework/Versions/3.9/lib/python3.9/json/__init__.py", line 346, in loads
    return _default_decoder.decode(s)
  File "/usr/local/Cellar/python@3.9/3.9.12/Frameworks/Python.framework/Versions/3.9/lib/python3.9/json/decoder.py", line 337, in decode
    obj, end = self.raw_decode(s, idx=_w(s, 0).end())
  File "/usr/local/Cellar/python@3.9/3.9.12/Frameworks/Python.framework/Versions/3.9/lib/python3.9/json/decoder.py", line 355, in raw_decode
    raise JSONDecodeError("Expecting value", s, err.value) from None
json.decoder.JSONDecodeError: Expecting value: line 1 column 1 (char 0)

During handling of the above exception, another exception occurred:

Traceback (most recent call last):
  File "/usr/local/lib/python3.9/site-packages/django/core/handlers/exception.py", line 55, in inner
    response = get_response(request)
  File "/usr/local/lib/python3.9/site-packages/django/core/handlers/base.py", line 197, in _get_response
    response = wrapped_callback(request, *callback_args, **callback_kwargs)
  File "/usr/local/lib/python3.9/site-packages/django/views/decorators/csrf.py", line 54, in wrapped_view
    return view_func(*args, **kwargs)
  File "/Users/monstar/Desktop/yang/python/real-image/code/django/real_image/process/views.py", line 60, in process_image
    return errResponse(e)
  File "/Users/monstar/Desktop/yang/python/real-image/code/django/real_image/process/views.py", line 69, in errResponse
    return HttpResponse(json.dumps(res, ensure_ascii=False),
  File "/usr/local/Cellar/python@3.9/3.9.12/Frameworks/Python.framework/Versions/3.9/lib/python3.9/json/__init__.py", line 234, in dumps
    return cls(
  File "/usr/local/Cellar/python@3.9/3.9.12/Frameworks/Python.framework/Versions/3.9/lib/python3.9/json/encoder.py", line 199, in encode
    chunks = self.iterencode(o, _one_shot=True)
  File "/usr/local/Cellar/python@3.9/3.9.12/Frameworks/Python.framework/Versions/3.9/lib/python3.9/json/encoder.py", line 257, in iterencode
    return _iterencode(o, 0)
  File "/usr/local/Cellar/python@3.9/3.9.12/Frameworks/Python.framework/Versions/3.9/lib/python3.9/json/encoder.py", line 179, in default
    raise TypeError(f'Object of type {o.__class__.__name__} '
TypeError: Object of type JSONDecodeError is not JSON serializable
[2022-12-12 02:22:46][ERROR][views.py:59:process_image]：Expecting value: line 1 column 1 (char 0)
[2022-12-12 02:22:46][ERROR][log.py:241:log_response]：Internal Server Error: /process/process_image
Traceback (most recent call last):
  File "/Users/monstar/Desktop/yang/python/real-image/code/django/real_image/process/views.py", line 20, in process_image
    requestBody = json.loads(request.body)
  File "/usr/local/Cellar/python@3.9/3.9.12/Frameworks/Python.framework/Versions/3.9/lib/python3.9/json/__init__.py", line 346, in loads
    return _default_decoder.decode(s)
  File "/usr/local/Cellar/python@3.9/3.9.12/Frameworks/Python.framework/Versions/3.9/lib/python3.9/json/decoder.py", line 337, in decode
    obj, end = self.raw_decode(s, idx=_w(s, 0).end())
  File "/usr/local/Cellar/python@3.9/3.9.12/Frameworks/Python.framework/Versions/3.9/lib/python3.9/json/decoder.py", line 355, in raw_decode
    raise JSONDecodeError("Expecting value", s, err.value) from None
json.decoder.JSONDecodeError: Expecting value: line 1 column 1 (char 0)

During handling of the above exception, another exception occurred:

Traceback (most recent call last):
  File "/usr/local/lib/python3.9/site-packages/django/core/handlers/exception.py", line 55, in inner
    response = get_response(request)
  File "/usr/local/lib/python3.9/site-packages/django/core/handlers/base.py", line 197, in _get_response
    response = wrapped_callback(request, *callback_args, **callback_kwargs)
  File "/usr/local/lib/python3.9/site-packages/django/views/decorators/csrf.py", line 54, in wrapped_view
    return view_func(*args, **kwargs)
  File "/Users/monstar/Desktop/yang/python/real-image/code/django/real_image/process/views.py", line 60, in process_image
    return errResponse(e)
  File "/Users/monstar/Desktop/yang/python/real-image/code/django/real_image/process/views.py", line 69, in errResponse
    return HttpResponse(json.dumps(res, ensure_ascii=False),
  File "/usr/local/Cellar/python@3.9/3.9.12/Frameworks/Python.framework/Versions/3.9/lib/python3.9/json/__init__.py", line 234, in dumps
    return cls(
  File "/usr/local/Cellar/python@3.9/3.9.12/Frameworks/Python.framework/Versions/3.9/lib/python3.9/json/encoder.py", line 199, in encode
    chunks = self.iterencode(o, _one_shot=True)
  File "/usr/local/Cellar/python@3.9/3.9.12/Frameworks/Python.framework/Versions/3.9/lib/python3.9/json/encoder.py", line 257, in iterencode
    return _iterencode(o, 0)
  File "/usr/local/Cellar/python@3.9/3.9.12/Frameworks/Python.framework/Versions/3.9/lib/python3.9/json/encoder.py", line 179, in default
    raise TypeError(f'Object of type {o.__class__.__name__} '
TypeError: Object of type JSONDecodeError is not JSON serializable
[2022-12-12 02:23:17][ERROR][views.py:59:process_image]：Expecting value: line 1 column 1 (char 0)
[2022-12-12 02:23:17][ERROR][log.py:241:log_response]：Internal Server Error: /process/process_image
Traceback (most recent call last):
  File "/Users/monstar/Desktop/yang/python/real-image/code/django/real_image/process/views.py", line 20, in process_image
    requestBody = json.loads(request.body)
  File "/usr/local/Cellar/python@3.9/3.9.12/Frameworks/Python.framework/Versions/3.9/lib/python3.9/json/__init__.py", line 346, in loads
    return _default_decoder.decode(s)
  File "/usr/local/Cellar/python@3.9/3.9.12/Frameworks/Python.framework/Versions/3.9/lib/python3.9/json/decoder.py", line 337, in decode
    obj, end = self.raw_decode(s, idx=_w(s, 0).end())
  File "/usr/local/Cellar/python@3.9/3.9.12/Frameworks/Python.framework/Versions/3.9/lib/python3.9/json/decoder.py", line 355, in raw_decode
    raise JSONDecodeError("Expecting value", s, err.value) from None
json.decoder.JSONDecodeError: Expecting value: line 1 column 1 (char 0)

During handling of the above exception, another exception occurred:

Traceback (most recent call last):
  File "/usr/local/lib/python3.9/site-packages/django/core/handlers/exception.py", line 55, in inner
    response = get_response(request)
  File "/usr/local/lib/python3.9/site-packages/django/core/handlers/base.py", line 197, in _get_response
    response = wrapped_callback(request, *callback_args, **callback_kwargs)
  File "/usr/local/lib/python3.9/site-packages/django/views/decorators/csrf.py", line 54, in wrapped_view
    return view_func(*args, **kwargs)
  File "/Users/monstar/Desktop/yang/python/real-image/code/django/real_image/process/views.py", line 60, in process_image
    return errResponse(e)
  File "/Users/monstar/Desktop/yang/python/real-image/code/django/real_image/process/views.py", line 69, in errResponse
    return HttpResponse(json.dumps(res, ensure_ascii=False),
  File "/usr/local/Cellar/python@3.9/3.9.12/Frameworks/Python.framework/Versions/3.9/lib/python3.9/json/__init__.py", line 234, in dumps
    return cls(
  File "/usr/local/Cellar/python@3.9/3.9.12/Frameworks/Python.framework/Versions/3.9/lib/python3.9/json/encoder.py", line 199, in encode
    chunks = self.iterencode(o, _one_shot=True)
  File "/usr/local/Cellar/python@3.9/3.9.12/Frameworks/Python.framework/Versions/3.9/lib/python3.9/json/encoder.py", line 257, in iterencode
    return _iterencode(o, 0)
  File "/usr/local/Cellar/python@3.9/3.9.12/Frameworks/Python.framework/Versions/3.9/lib/python3.9/json/encoder.py", line 179, in default
    raise TypeError(f'Object of type {o.__class__.__name__} '
TypeError: Object of type JSONDecodeError is not JSON serializable
[2022-12-12 02:49:39][WARNING][log.py:241:log_response]：Not Found: /
