[2022-12-08 06:07:10][ERROR][views.py:53:process_image]：[Errno 2] No such file or directory: '/Users/monstar/Desktop/yang/python/real-image/code/django/real_image/real_image/image/input/2022-12-08/1670479630_288.jpeg'
[2022-12-08 06:07:10][ERROR][log.py:241:log_response]：Internal Server Error: /process/process_image
Traceback (most recent call last):
  File "/Users/monstar/Desktop/yang/python/real-image/code/django/real_image/process/views.py", line 43, in process_image
    with open(input_image_path, 'wb') as f:
FileNotFoundError: [Errno 2] No such file or directory: '/Users/monstar/Desktop/yang/python/real-image/code/django/real_image/real_image/image/input/2022-12-08/1670479630_288.jpeg'

During handling of the above exception, another exception occurred:

Traceback (most recent call last):
  File "/usr/local/Cellar/python@3.9/3.9.12/Frameworks/Python.framework/Versions/3.9/lib/python3.9/site-packages/django/core/handlers/exception.py", line 55, in inner
    response = get_response(request)
  File "/usr/local/Cellar/python@3.9/3.9.12/Frameworks/Python.framework/Versions/3.9/lib/python3.9/site-packages/django/core/handlers/base.py", line 197, in _get_response
    response = wrapped_callback(request, *callback_args, **callback_kwargs)
  File "/usr/local/Cellar/python@3.9/3.9.12/Frameworks/Python.framework/Versions/3.9/lib/python3.9/site-packages/django/views/decorators/csrf.py", line 54, in wrapped_view
    return view_func(*args, **kwargs)
  File "/Users/monstar/Desktop/yang/python/real-image/code/django/real_image/process/views.py", line 54, in process_image
    return errResponse(e)
  File "/Users/monstar/Desktop/yang/python/real-image/code/django/real_image/process/views.py", line 63, in errResponse
    return HttpResponse(json.dumps(res, ensure_ascii=False),
  File "/usr/local/Cellar/python@3.9/3.9.12/Frameworks/Python.framework/Versions/3.9/lib/python3.9/json/__init__.py", line 234, in dumps
    return cls(
  File "/usr/local/Cellar/python@3.9/3.9.12/Frameworks/Python.framework/Versions/3.9/lib/python3.9/json/encoder.py", line 199, in encode
    chunks = self.iterencode(o, _one_shot=True)
  File "/usr/local/Cellar/python@3.9/3.9.12/Frameworks/Python.framework/Versions/3.9/lib/python3.9/json/encoder.py", line 257, in iterencode
    return _iterencode(o, 0)
  File "/usr/local/Cellar/python@3.9/3.9.12/Frameworks/Python.framework/Versions/3.9/lib/python3.9/json/encoder.py", line 179, in default
    raise TypeError(f'Object of type {o.__class__.__name__} '
TypeError: Object of type FileNotFoundError is not JSON serializable
[2022-12-08 06:07:10][ERROR][basehttp.py:187:log_message]："POST /process/process_image HTTP/1.1" 500 140027
[2022-12-08 06:12:21][WARNING][log.py:241:log_response]：Not Found: /process/media/output/2022-12-08/1670479886_831.jpeg
[2022-12-08 06:12:21][WARNING][basehttp.py:187:log_message]："GET /process/media/output/2022-12-08/1670479886_831.jpeg HTTP/1.1" 404 2883
[2022-12-08 06:30:13][WARNING][log.py:241:log_response]：Not Found: /favicon.ico
[2022-12-08 07:05:53][WARNING][log.py:241:log_response]：Not Found: /process/media/2022-12-08/1670479886_831.jpeg
[2022-12-08 07:06:55][WARNING][log.py:241:log_response]：Not Found: /process/media/2022-12-08/1670479886_831.jpeg
[2022-12-08 07:06:55][WARNING][log.py:241:log_response]：Not Found: /process/media/
